Workbook

Sheet Sheet1
A3: Region | B3: Buildings | C3: Industry | D3: Total | E3: Split Buildings | F3: Split Industry | G3: Column1
A4: AT | B4: 58.968 | C4: 11.232 | D4: =SUM(Table1[[#This Row],[Buildings]:[Industry]]) -> 70.2 | E4: =ROUND(Table1[[#This Row],[Buildings]]/Table1[[#This Row],[Total]],2) -> 0.84 | F4: =ROUND(Table1[[#This Row],[Industry]]/Table1[[#This Row],[Total]],2) -> 0.16
A5: BE | B5: 0.9329 | C5: 0.3451 | D5: =SUM(Table1[[#This Row],[Buildings]:[Industry]]) -> 1.278 | E5: =ROUND(Table1[[#This Row],[Buildings]]/Table1[[#This Row],[Total]],2) -> 0.73 | F5: =ROUND(Table1[[#This Row],[Industry]]/Table1[[#This Row],[Total]],2) -> 0.27
A6: BG | B6: 18.2232 | C6: 2.2644 | D6: =SUM(Table1[[#This Row],[Buildings]:[Industry]]) -> 20.4876 | E6: =ROUND(Table1[[#This Row],[Buildings]]/Table1[[#This Row],[Total]],2) -> 0.89 | F6: =ROUND(Table1[[#This Row],[Industry]]/Table1[[#This Row],[Total]],2) -> 0.11
A7: CH | D7: =SUM(Table1[[#This Row],[Buildings]:[Industry]]) -> 0 | E7: 0 | F7: 0
A8: CZ | B8: 39.9636 | C8: 20.4948 | D8: =SUM(Table1[[#This Row],[Buildings]:[Industry]]) -> 60.4584 | E8: =ROUND(Table1[[#This Row],[Buildings]]/Table1[[#This Row],[Total]],2) -> 0.66 | F8: =ROUND(Table1[[#This Row],[Industry]]/Table1[[#This Row],[Total]],2) -> 0.34
A9: DE | B9: 289.3716 | C9: 79.3548 | D9: =SUM(Table1[[#This Row],[Buildings]:[Industry]]) -> 368.7264 | E9: =ROUND(Table1[[#This Row],[Buildings]]/Table1[[#This Row],[Total]],2) -> 0.78 | F9: =ROUND(Table1[[#This Row],[Industry]]/Table1[[#This Row],[Total]],2) -> 0.22
A10: DK | B10: 104.9184 | C10: 5.076 | D10: =SUM(Table1[[#This Row],[Buildings]:[Industry]]) -> 109.9944 | E10: =ROUND(Table1[[#This Row],[Buildings]]/Table1[[#This Row],[Total]],2) -> 0.95 | F10: =ROUND(Table1[[#This Row],[Industry]]/Table1[[#This Row],[Total]],2) -> 0.05
A11: EE | B11: 18.1584 | C11: 1.4976 | D11: =SUM(Table1[[#This Row],[Buildings]:[Industry]]) -> 19.656 | E11: =ROUND(Table1[[#This Row],[Buildings]]/Table1[[#This Row],[Total]],2) -> 0.92 | F11: =ROUND(Table1[[#This Row],[Industry]]/Table1[[#This Row],[Total]],2) -> 0.08
A12: ES | B12: 1.4976 | C12: 0.4212 | D12: =SUM(Table1[[#This Row],[Buildings]:[Industry]]) -> 1.9188 | E12: =ROUND(Table1[[#This Row],[Buildings]]/Table1[[#This Row],[Total]],2) -> 0.78 | F12: =ROUND(Table1[[#This Row],[Industry]]/Table1[[#This Row],[Total]],2) -> 0.22
A13: FI | B13: 109.674 | C13: 10.926 | D13: =SUM(Table1[[#This Row],[Buildings]:[Industry]]) -> 120.6 | E13: =ROUND(Table1[[#This Row],[Buildings]]/Table1[[#This Row],[Total]],2) -> 0.91 | F13: =ROUND(Table1[[#This Row],[Industry]]/Table1[[#This Row],[Total]],2) -> 0.09
A14: FR | B14: 79.2 | C14: 12.24 | D14: =SUM(Table1[[#This Row],[Buildings]:[Industry]]) -> 91.44 | E14: =ROUND(Table1[[#This Row],[Buildings]]/Table1[[#This Row],[Total]],2) -> 0.87 | F14: =ROUND(Table1[[#This Row],[Industry]]/Table1[[#This Row],[Total]],2) -> 0.13
A15: GR | B15: 3.5 | C15: 0 | D15: =SUM(Table1[[#This Row],[Buildings]:[Industry]]) -> 3.5 | E15: =ROUND(Table1[[#This Row],[Buildings]]/Table1[[#This Row],[Total]],2) -> 1 | F15: =ROUND(Table1[[#This Row],[Industry]]/Table1[[#This Row],[Total]],2) -> 0
A16: HR | B16: 6.0624 | C16: 1.1304 | D16: =SUM(Table1[[#This Row],[Buildings]:[Industry]]) -> 7.1928 | E16: =ROUND(Table1[[#This Row],[Buildings]]/Table1[[#This Row],[Total]],2) -> 0.84 | F16: =ROUND(Table1[[#This Row],[Industry]]/Table1[[#This Row],[Total]],2) -> 0.16
A17: HU | B17: 25.9452 | C17: 0 | D17: =SUM(Table1[[#This Row],[Buildings]:[Industry]]) -> 25.9452 | E17: =ROUND(Table1[[#This Row],[Buildings]]/Table1[[#This Row],[Total]],2) -> 1 | F17: =ROUND(Table1[[#This Row],[Industry]]/Table1[[#This Row],[Total]],2) -> 0
A18: IE | B18: 0 | C18: 0 | D18: =SUM(Table1[[#This Row],[Buildings]:[Industry]]) -> 0 | E18: 0 | F18: 0
A19: IT | B19: 32.4 | C19: 1.0404 | D19: =SUM(Table1[[#This Row],[Buildings]:[Industry]]) -> 33.4404 | E19: =ROUND(Table1[[#This Row],[Buildings]]/Table1[[#This Row],[Total]],2) -> 0.97 | F19: =ROUND(Table1[[#This Row],[Industry]]/Table1[[#This Row],[Total]],2) -> 0.03
A20: LT | B20: 27.522 | C20: 0 | D20: =SUM(Table1[[#This Row],[Buildings]:[Industry]]) -> 27.522 | E20: =ROUND(Table1[[#This Row],[Buildings]]/Table1[[#This Row],[Total]],2) -> 1 | F20: =ROUND(Table1[[#This Row],[Industry]]/Table1[[#This Row],[Total]],2) -> 0
A21: LU | B21: 3.0708 | C21: 0.0216 | D21: =SUM(Table1[[#This Row],[Buildings]:[Industry]]) -> 3.0924 | E21: =ROUND(Table1[[#This Row],[Buildings]]/Table1[[#This Row],[Total]],2) -> 0.99 | F21: =ROUND(Table1[[#This Row],[Industry]]/Table1[[#This Row],[Total]],2) -> 0.01
A22: LV | B22: 20.934 | C22: 3.3912 | D22: =SUM(Table1[[#This Row],[Buildings]:[Industry]]) -> 24.3252 | E22: =ROUND(Table1[[#This Row],[Buildings]]/Table1[[#This Row],[Total]],2) -> 0.86 | F22: =ROUND(Table1[[#This Row],[Industry]]/Table1[[#This Row],[Total]],2) -> 0.14
A23: NL | B23: 18.1152 | C23: 4.68 | D23: =SUM(Table1[[#This Row],[Buildings]:[Industry]]) -> 22.7952 | E23: =ROUND(Table1[[#This Row],[Buildings]]/Table1[[#This Row],[Total]],2) -> 0.79 | F23: =ROUND(Table1[[#This Row],[Industry]]/Table1[[#This Row],[Total]],2) -> 0.21
A24: NO | B24: 17.5572 | C24: 2.7576 | D24: =SUM(Table1[[#This Row],[Buildings]:[Industry]]) -> 20.3148 | E24: =ROUND(Table1[[#This Row],[Buildings]]/Table1[[#This Row],[Total]],2) -> 0.86 | F24: =ROUND(Table1[[#This Row],[Industry]]/Table1[[#This Row],[Total]],2) -> 0.14
A25: NONEU_Balkan | D25: =SUM(Table1[[#This Row],[Buildings]:[Industry]]) -> 0 | E25: 0 | F25: 0
A26: PL | B26: 198.81 | C26: 34.6464 | D26: =SUM(Table1[[#This Row],[Buildings]:[Industry]]) -> 233.4564 | E26: =ROUND(Table1[[#This Row],[Buildings]]/Table1[[#This Row],[Total]],2) -> 0.85 | F26: =ROUND(Table1[[#This Row],[Industry]]/Table1[[#This Row],[Total]],2) -> 0.15
A27: PT | B27: 0.1548 | C27: 0 | D27: =SUM(Table1[[#This Row],[Buildings]:[Industry]]) -> 0.1548 | E27: =ROUND(Table1[[#This Row],[Buildings]]/Table1[[#This Row],[Total]],2) -> 1 | F27: =ROUND(Table1[[#This Row],[Industry]]/Table1[[#This Row],[Total]],2) -> 0
A28: RO | B28: 35.5896 | C28: 0 | D28: =SUM(Table1[[#This Row],[Buildings]:[Industry]]) -> 35.5896 | E28: =ROUND(Table1[[#This Row],[Buildings]]/Table1[[#This Row],[Total]],2) -> 1 | F28: =ROUND(Table1[[#This Row],[Industry]]/Table1[[#This Row],[Total]],2) -> 0
A29: SE | B29: 161.6076 | C29: 21.816 | D29: =SUM(Table1[[#This Row],[Buildings]:[Industry]]) -> 183.4236 | E29: =ROUND(Table1[[#This Row],[Buildings]]/Table1[[#This Row],[Total]],2) -> 0.88 | F29: =ROUND(Table1[[#This Row],[Industry]]/Table1[[#This Row],[Total]],2) -> 0.12
A30: SI | B30: 5.5476 | C30: 1.2816 | D30: =SUM(Table1[[#This Row],[Buildings]:[Industry]]) -> 6.8292 | E30: =ROUND(Table1[[#This Row],[Buildings]]/Table1[[#This Row],[Total]],2) -> 0.81 | F30: =ROUND(Table1[[#This Row],[Industry]]/Table1[[#This Row],[Total]],2) -> 0.19
A31: SK | B31: 31.4316 | C31: 19.944 | D31: =SUM(Table1[[#This Row],[Buildings]:[Industry]]) -> 51.3756 | E31: =ROUND(Table1[[#This Row],[Buildings]]/Table1[[#This Row],[Total]],2) -> 0.61 | F31: =ROUND(Table1[[#This Row],[Industry]]/Table1[[#This Row],[Total]],2) -> 0.39
A32: TR | D32: =SUM(Table1[[#This Row],[Buildings]:[Industry]]) -> 0 | E32: 0 | F32: 0
A33: UK | B33: 43.2 | C33: 0 | D33: =SUM(Table1[[#This Row],[Buildings]:[Industry]]) -> 43.2 | E33: =ROUND(Table1[[#This Row],[Buildings]]/Table1[[#This Row],[Total]],2) -> 1 | F33: =ROUND(Table1[[#This Row],[Industry]]/Table1[[#This Row],[Total]],2) -> 0

Sheet Sheet2
A3: Region | B3: Sector | C3: 2018 | D3: 2020 | E3: 2021 | F3: 2025 | G3: 2030 | H3: 2035 | I3: 2040 | J3: 2045 | K3: 2050 | L3: 2055 | M3: 2060 | Q3: Region | R3: Sector | S3: 2018 | T3: 2020 | U3: 2021 | V3: 2025 | W3: 2030 | X3: 2035 | Y3: 2040 | Z3: 2045 | AA3: 2050 | AB3: 2055 | AC3: 2060
A4: AT | B4: Buildings | C4: =SUMIF(Table1[Region],Sheet2!A4,Table1[Split Buildings]) -> 0.84 | D4: =$C4 -> 0.84 | E4: =$C4 -> 0.84 | F4: =$C4 -> 0.84 | G4: =F4+($K4-$F4)/5 -> 0.798 | H4: =G4+($K4-$F4)/5 -> 0.756 | I4: =H4+($K4-$F4)/5 -> 0.714 | J4: =I4+($K4-$F4)/5 -> 0.672 | K4: =F4*0.75 -> 0.63 | L4: =$K4 -> 0.63 | M4: =$K4 -> 0.63 | Q4: AT | R4: Industry | S4: =SUMIF(Table1[Region],Sheet2!Q4,Table1[Split Industry]) -> 0.16 | T4: =$S4 -> 0.16 | U4: =$S4 -> 0.16 | V4: =$S4 -> 0.16 | W4: =V4+($AA4-$V4)/5 -> 0.152 | X4: =W4+($AA4-$V4)/5 -> 0.144 | Y4: =X4+($AA4-$V4)/5 -> 0.136 | Z4: =Y4+($AA4-$V4)/5 -> 0.128 | AA4: =V4*0.75 -> 0.12 | AB4: =$AA4 -> 0.12 | AC4: =$AA4 -> 0.12
A5: BE | B5: Buildings | C5: =SUMIF(Table1[Region],Sheet2!A5,Table1[Split Buildings]) -> 0.73 | D5: =$C5 -> 0.73 | E5: =$C5 -> 0.73 | F5: =$C5 -> 0.73 | G5: =F5+($K5-$F5)/5 -> 0.6935 | H5: =G5+($K5-$F5)/5 -> 0.657 | I5: =H5+($K5-$F5)/5 -> 0.6205 | J5: =I5+($K5-$F5)/5 -> 0.584 | K5: =F5*0.75 -> 0.5475 | L5: =$K5 -> 0.5475 | M5: =$K5 -> 0.5475 | Q5: BE | R5: Industry | S5: =SUMIF(Table1[Region],Sheet2!Q5,Table1[Split Industry]) -> 0.27 | T5: =$S5 -> 0.27 | U5: =$S5 -> 0.27 | V5: =$S5 -> 0.27 | W5: =V5+($AA5-$V5)/5 -> 0.2565 | X5: =W5+($AA5-$V5)/5 -> 0.243 | Y5: =X5+($AA5-$V5)/5 -> 0.2295 | Z5: =Y5+($AA5-$V5)/5 -> 0.216 | AA5: =V5*0.75 -> 0.2025 | AB5: =$AA5 -> 0.2025 | AC5: =$AA5 -> 0.2025
A6: BG | B6: Buildings | C6: =SUMIF(Table1[Region],Sheet2!A6,Table1[Split Buildings]) -> 0.89 | D6: =$C6 -> 0.89 | E6: =$C6 -> 0.89 | F6: =$C6 -> 0.89 | G6: =F6+($K6-$F6)/5 -> 0.8455 | H6: =G6+($K6-$F6)/5 -> 0.801 | I6: =H6+($K6-$F6)/5 -> 0.7565 | J6: =I6+($K6-$F6)/5 -> 0.712 | K6: =F6*0.75 -> 0.6675 | L6: =$K6 -> 0.6675 | M6: =$K6 -> 0.6675 | Q6: BG | R6: Industry | S6: =SUMIF(Table1[Region],Sheet2!Q6,Table1[Split Industry]) -> 0.11 | T6: =$S6 -> 0.11 | U6: =$S6 -> 0.11 | V6: =$S6 -> 0.11 | W6: =V6+($AA6-$V6)/5 -> 0.1045 | X6: =W6+($AA6-$V6)/5 -> 0.099 | Y6: =X6+($AA6-$V6)/5 -> 0.0935 | Z6: =Y6+($AA6-$V6)/5 -> 0.088 | AA6: =V6*0.75 -> 0.0825 | AB6: =$AA6 -> 0.0825 | AC6: =$AA6 -> 0.0825
A7: CH | B7: Buildings | C7: =SUMIF(Table1[Region],Sheet2!A7,Table1[Split Buildings]) -> 0 | D7: =$C7 -> 0 | E7: =$C7 -> 0 | F7: =$C7 -> 0 | G7: =F7+($K7-$F7)/5 -> 0 | H7: =G7+($K7-$F7)/5 -> 0 | I7: =H7+($K7-$F7)/5 -> 0 | J7: =I7+($K7-$F7)/5 -> 0 | K7: =F7*0.75 -> 0 | L7: =$K7 -> 0 | M7: =$K7 -> 0 | Q7: CH | R7: Industry | S7: =SUMIF(Table1[Region],Sheet2!Q7,Table1[Split Industry]) -> 0 | T7: =$S7 -> 0 | U7: =$S7 -> 0 | V7: =$S7 -> 0 | W7: =V7+($AA7-$V7)/5 -> 0 | X7: =W7+($AA7-$V7)/5 -> 0 | Y7: =X7+($AA7-$V7)/5 -> 0 | Z7: =Y7+($AA7-$V7)/5 -> 0 | AA7: =V7*0.75 -> 0 | AB7: =$AA7 -> 0 | AC7: =$AA7 -> 0
A8: CZ | B8: Buildings | C8: =SUMIF(Table1[Region],Sheet2!A8,Table1[Split Buildings]) -> 0.66 | D8: =$C8 -> 0.66 | E8: =$C8 -> 0.66 | F8: =$C8 -> 0.66 | G8: =F8+($K8-$F8)/5 -> 0.627 | H8: =G8+($K8-$F8)/5 -> 0.594 | I8: =H8+($K8-$F8)/5 -> 0.561 | J8: =I8+($K8-$F8)/5 -> 0.528 | K8: =F8*0.75 -> 0.495 | L8: =$K8 -> 0.495 | M8: =$K8 -> 0.495 | Q8: CZ | R8: Industry | S8: =SUMIF(Table1[Region],Sheet2!Q8,Table1[Split Industry]) -> 0.34 | T8: =$S8 -> 0.34 | U8: =$S8 -> 0.34 | V8: =$S8 -> 0.34 | W8: =V8+($AA8-$V8)/5 -> 0.323 | X8: =W8+($AA8-$V8)/5 -> 0.306 | Y8: =X8+($AA8-$V8)/5 -> 0.289 | Z8: =Y8+($AA8-$V8)/5 -> 0.272 | AA8: =V8*0.75 -> 0.255 | AB8: =$AA8 -> 0.255 | AC8: =$AA8 -> 0.255
A9: DE | B9: Buildings | C9: =SUMIF(Table1[Region],Sheet2!A9,Table1[Split Buildings]) -> 0.78 | D9: =$C9 -> 0.78 | E9: =$C9 -> 0.78 | F9: =$C9 -> 0.78 | G9: =F9+($K9-$F9)/5 -> 0.741 | H9: =G9+($K9-$F9)/5 -> 0.702 | I9: =H9+($K9-$F9)/5 -> 0.663 | J9: =I9+($K9-$F9)/5 -> 0.624 | K9: =F9*0.75 -> 0.585 | L9: =$K9 -> 0.585 | M9: =$K9 -> 0.585 | Q9: DE | R9: Industry | S9: =SUMIF(Table1[Region],Sheet2!Q9,Table1[Split Industry]) -> 0.22 | T9: =$S9 -> 0.22 | U9: =$S9 -> 0.22 | V9: =$S9 -> 0.22 | W9: =V9+($AA9-$V9)/5 -> 0.209 | X9: =W9+($AA9-$V9)/5 -> 0.198 | Y9: =X9+($AA9-$V9)/5 -> 0.187 | Z9: =Y9+($AA9-$V9)/5 -> 0.176 | AA9: =V9*0.75 -> 0.165 | AB9: =$AA9 -> 0.165 | AC9: =$AA9 -> 0.165
A10: DK | B10: Buildings | C10: =SUMIF(Table1[Region],Sheet2!A10,Table1[Split Buildings]) -> 0.95 | D10: =$C10 -> 0.95 | E10: =$C10 -> 0.95 | F10: =$C10 -> 0.95 | G10: =F10+($K10-$F10)/5 -> 0.9025 | H10: =G10+($K10-$F10)/5 -> 0.855 | I10: =H10+($K10-$F10)/5 -> 0.8075 | J10: =I10+($K10-$F10)/5 -> 0.76 | K10: =F10*0.75 -> 0.7125 | L10: =$K10 -> 0.7125 | M10: =$K10 -> 0.7125 | Q10: DK | R10: Industry | S10: =SUMIF(Table1[Region],Sheet2!Q10,Table1[Split Industry]) -> 0.05 | T10: =$S10 -> 0.05 | U10: =$S10 -> 0.05 | V10: =$S10 -> 0.05 | W10: =V10+($AA10-$V10)/5 -> 0.0475 | X10: =W10+($AA10-$V10)/5 -> 0.045 | Y10: =X10+($AA10-$V10)/5 -> 0.0425 | Z10: =Y10+($AA10-$V10)/5 -> 0.04 | AA10: =V10*0.75 -> 0.0375 | AB10: =$AA10 -> 0.0375 | AC10: =$AA10 -> 0.0375
A11: EE | B11: Buildings | C11: =SUMIF(Table1[Region],Sheet2!A11,Table1[Split Buildings]) -> 0.92 | D11: =$C11 -> 0.92 | E11: =$C11 -> 0.92 | F11: =$C11 -> 0.92 | G11: =F11+($K11-$F11)/5 -> 0.874 | H11: =G11+($K11-$F11)/5 -> 0.828 | I11: =H11+($K11-$F11)/5 -> 0.782 | J11: =I11+($K11-$F11)/5 -> 0.736 | K11: =F11*0.75 -> 0.69 | L11: =$K11 -> 0.69 | M11: =$K11 -> 0.69 | Q11: EE | R11: Industry | S11: =SUMIF(Table1[Region],Sheet2!Q11,Table1[Split Industry]) -> 0.08 | T11: =$S11 -> 0.08 | U11: =$S11 -> 0.08 | V11: =$S11 -> 0.08 | W11: =V11+($AA11-$V11)/5 -> 0.076 | X11: =W11+($AA11-$V11)/5 -> 0.072 | Y11: =X11+($AA11-$V11)/5 -> 0.068 | Z11: =Y11+($AA11-$V11)/5 -> 0.064 | AA11: =V11*0.75 -> 0.06 | AB11: =$AA11 -> 0.06 | AC11: =$AA11 -> 0.06
A12: ES | B12: Buildings | C12: =SUMIF(Table1[Region],Sheet2!A12,Table1[Split Buildings]) -> 0.78 | D12: =$C12 -> 0.78 | E12: =$C12 -> 0.78 | F12: =$C12 -> 0.78 | G12: =F12+($K12-$F12)/5 -> 0.741 | H12: =G12+($K12-$F12)/5 -> 0.702 | I12: =H12+($K12-$F12)/5 -> 0.663 | J12: =I12+($K12-$F12)/5 -> 0.624 | K12: =F12*0.75 -> 0.585 | L12: =$K12 -> 0.585 | M12: =$K12 -> 0.585 | Q12: ES | R12: Industry | S12: =SUMIF(Table1[Region],Sheet2!Q12,Table1[Split Industry]) -> 0.22 | T12: =$S12 -> 0.22 | U12: =$S12 -> 0.22 | V12: =$S12 -> 0.22 | W12: =V12+($AA12-$V12)/5 -> 0.209 | X12: =W12+($AA12-$V12)/5 -> 0.198 | Y12: =X12+($AA12-$V12)/5 -> 0.187 | Z12: =Y12+($AA12-$V12)/5 -> 0.176 | AA12: =V12*0.75 -> 0.165 | AB12: =$AA12 -> 0.165 | AC12: =$AA12 -> 0.165
A13: FI | B13: Buildings | C13: =SUMIF(Table1[Region],Sheet2!A13,Table1[Split Buildings]) -> 0.91 | D13: =$C13 -> 0.91 | E13: =$C13 -> 0.91 | F13: =$C13 -> 0.91 | G13: =F13+($K13-$F13)/5 -> 0.8645 | H13: =G13+($K13-$F13)/5 -> 0.819 | I13: =H13+($K13-$F13)/5 -> 0.7735 | J13: =I13+($K13-$F13)/5 -> 0.728 | K13: =F13*0.75 -> 0.6825 | L13: =$K13 -> 0.6825 | M13: =$K13 -> 0.6825 | Q13: FI | R13: Industry | S13: =SUMIF(Table1[Region],Sheet2!Q13,Table1[Split Industry]) -> 0.09 | T13: =$S13 -> 0.09 | U13: =$S13 -> 0.09 | V13: =$S13 -> 0.09 | W13: =V13+($AA13-$V13)/5 -> 0.0855 | X13: =W13+($AA13-$V13)/5 -> 0.081 | Y13: =X13+($AA13-$V13)/5 -> 0.0765 | Z13: =Y13+($AA13-$V13)/5 -> 0.072 | AA13: =V13*0.75 -> 0.0675 | AB13: =$AA13 -> 0.0675 | AC13: =$AA13 -> 0.0675
A14: FR | B14: Buildings | C14: =SUMIF(Table1[Region],Sheet2!A14,Table1[Split Buildings]) -> 0.87 | D14: =$C14 -> 0.87 | E14: =$C14 -> 0.87 | F14: =$C14 -> 0.87 | G14: =F14+($K14-$F14)/5 -> 0.8265 | H14: =G14+($K14-$F14)/5 -> 0.783 | I14: =H14+($K14-$F14)/5 -> 0.7395 | J14: =I14+($K14-$F14)/5 -> 0.696 | K14: =F14*0.75 -> 0.6525 | L14: =$K14 -> 0.6525 | M14: =$K14 -> 0.6525 | Q14: FR | R14: Industry | S14: =SUMIF(Table1[Region],Sheet2!Q14,Table1[Split Industry]) -> 0.13 | T14: =$S14 -> 0.13 | U14: =$S14 -> 0.13 | V14: =$S14 -> 0.13 | W14: =V14+($AA14-$V14)/5 -> 0.1235 | X14: =W14+($AA14-$V14)/5 -> 0.117 | Y14: =X14+($AA14-$V14)/5 -> 0.1105 | Z14: =Y14+($AA14-$V14)/5 -> 0.104 | AA14: =V14*0.75 -> 0.0975 | AB14: =$AA14 -> 0.0975 | AC14: =$AA14 -> 0.0975
A15: GR | B15: Buildings | C15: =SUMIF(Table1[Region],Sheet2!A15,Table1[Split Buildings]) -> 1 | D15: =$C15 -> 1 | E15: =$C15 -> 1 | F15: =$C15 -> 1 | G15: =F15+($K15-$F15)/5 -> 0.95 | H15: =G15+($K15-$F15)/5 -> 0.9 | I15: =H15+($K15-$F15)/5 -> 0.85 | J15: =I15+($K15-$F15)/5 -> 0.8 | K15: =F15*0.75 -> 0.75 | L15: =$K15 -> 0.75 | M15: =$K15 -> 0.75 | Q15: GR | R15: Industry | S15: =SUMIF(Table1[Region],Sheet2!Q15,Table1[Split Industry]) -> 0 | T15: =$S15 -> 0 | U15: =$S15 -> 0 | V15: =$S15 -> 0 | W15: =V15+($AA15-$V15)/5 -> 0 | X15: =W15+($AA15-$V15)/5 -> 0 | Y15: =X15+($AA15-$V15)/5 -> 0 | Z15: =Y15+($AA15-$V15)/5 -> 0 | AA15: =V15*0.75 -> 0 | AB15: =$AA15 -> 0 | AC15: =$AA15 -> 0
... A33: UK | B33: Buildings | C33: =SUMIF(Table1[Region],Sheet2!A33,Table1[Split Buildings]) -> 1 | D33: =$C33 -> 1 | E33: =$C33 -> 1 | F33: =$C33 -> 1 | G33: =F33+($K33-$F33)/5 -> 0.95 | H33: =G33+($K33-$F33)/5 -> 0.9 | I33: =H33+($K33-$F33)/5 -> 0.85 | J33: =I33+($K33-$F33)/5 -> 0.8 | K33: =F33*0.75 -> 0.75 | L33: =$K33 -> 0.75 | M33: =$K33 -> 0.75 | Q33: UK | R33: Industry | S33: =SUMIF(Table1[Region],Sheet2!Q33,Table1[Split Industry]) -> 0 | T33: =$S33 -> 0 | U33: =$S33 -> 0 | V33: =$S33 -> 0 | W33: =V33+($AA33-$V33)/5 -> 0 | X33: =W33+($AA33-$V33)/5 -> 0 | Y33: =X33+($AA33-$V33)/5 -> 0 | Z33: =Y33+($AA33-$V33)/5 -> 0 | AA33: =V33*0.75 -> 0 | AB33: =$AA33 -> 0 | AC33: =$AA33 -> 0
A39: Region | B39: Sector | C39: 2018 | D39: 2020 | E39: 2021 | F39: 2025 | G39: 2030 | H39: 2035 | I39: 2040 | J39: 2045 | K39: 2050 | L39: 2055 | M39: 2060
A40: =A4 -> AT | B40: =B4 -> Buildings | C40: =C4 -> 0.84 | D40: =D4 -> 0.84 | E40: =E4 -> 0.84 | F40: =F4 -> 0.84 | G40: =G4 -> 0.798 | H40: =H4 -> 0.756 | ... M40: =M4 -> 0.63
A41: =A5 -> BE | B41: =B5 -> Buildings | C41: =C5 -> 0.73 | D41: =D5 -> 0.73 | E41: =E5 -> 0.73 | F41: =F5 -> 0.73 | G41: =G5 -> 0.6935 | H41: =H5 -> 0.657 | ... M41: =M5 -> 0.5475
A42: =A6 -> BG | B42: =B6 -> Buildings | C42: =C6 -> 0.89 | D42: =D6 -> 0.89 | E42: =E6 -> 0.89 | F42: =F6 -> 0.89 | G42: =G6 -> 0.8455 | H42: =H6 -> 0.801 | ... M42: =M6 -> 0.6675
A43: =A7 -> CH | B43: =B7 -> Buildings | C43: =C7 -> 0 | D43: =D7 -> 0 | E43: =E7 -> 0 | F43: =F7 -> 0 | G43: =G7 -> 0 | H43: =H7 -> 0 | ... M43: =M7 -> 0
A44: =A8 -> CZ | B44: =B8 -> Buildings | C44: =C8 -> 0.66 | D44: =D8 -> 0.66 | E44: =E8 -> 0.66 | F44: =F8 -> 0.66 | G44: =G8 -> 0.627 | H44: =H8 -> 0.594 | ... M44: =M8 -> 0.495
A45: =A9 -> DE | B45: =B9 -> Buildings | C45: =C9 -> 0.78 | D45: =D9 -> 0.78 | E45: =E9 -> 0.78 | F45: =F9 -> 0.78 | G45: =G9 -> 0.741 | H45: =H9 -> 0.702 | ... M45: =M9 -> 0.585
A46: =A10 -> DK | B46: =B10 -> Buildings | C46: =C10 -> 0.95 | D46: =D10 -> 0.95 | E46: =E10 -> 0.95 | F46: =F10 -> 0.95 | G46: =G10 -> 0.9025 | H46: =H10 -> 0.855 | ... M46: =M10 -> 0.7125
A47: =A11 -> EE | B47: =B11 -> Buildings | C47: =C11 -> 0.92 | D47: =D11 -> 0.92 | E47: =E11 -> 0.92 | F47: =F11 -> 0.92 | G47: =G11 -> 0.874 | H47: =H11 -> 0.828 | ... M47: =M11 -> 0.69
A48: =A12 -> ES | B48: =B12 -> Buildings | C48: =C12 -> 0.78 | D48: =D12 -> 0.78 | E48: =E12 -> 0.78 | F48: =F12 -> 0.78 | G48: =G12 -> 0.741 | H48: =H12 -> 0.702 | ... M48: =M12 -> 0.585
A49: =A13 -> FI | B49: =B13 -> Buildings | C49: =C13 -> 0.91 | D49: =D13 -> 0.91 | E49: =E13 -> 0.91 | F49: =F13 -> 0.91 | G49: =G13 -> 0.8645 | H49: =H13 -> 0.819 | ... M49: =M13 -> 0.6825
A50: =A14 -> FR | B50: =B14 -> Buildings | C50: =C14 -> 0.87 | D50: =D14 -> 0.87 | E50: =E14 -> 0.87 | F50: =F14 -> 0.87 | G50: =G14 -> 0.8265 | H50: =H14 -> 0.783 | ... M50: =M14 -> 0.6525
A51: =A15 -> GR | B51: =B15 -> Buildings | C51: =C15 -> 1 | D51: =D15 -> 1 | E51: =E15 -> 1 | F51: =F15 -> 1 | G51: =G15 -> 0.95 | H51: =H15 -> 0.9 | ... M51: =M15 -> 0.75
... A69: =A33 -> UK | B69: =B33 -> Buildings | C69: =C33 -> 1 | D69: =D33 -> 1 | E69: =E33 -> 1 | F69: =F33 -> 1 | G69: =G33 -> 0.95 | H69: =H33 -> 0.9 | ... M69: =M33 -> 0.75
A70: =Q4 -> AT | B70: =R4 -> Industry | C70: =S4 -> 0.16 | D70: =T4 -> 0.16 | E70: =U4 -> 0.16 | F70: =V4 -> 0.16 | G70: =W4 -> 0.152 | H70: =X4 -> 0.144 | ... M70: =AC4 -> 0.12
A71: =Q5 -> BE | B71: =R5 -> Industry | C71: =S5 -> 0.27 | D71: =T5 -> 0.27 | E71: =U5 -> 0.27 | F71: =V5 -> 0.27 | G71: =W5 -> 0.2565 | H71: =X5 -> 0.243 | ... M71: =AC5 -> 0.2025
A72: =Q6 -> BG | B72: =R6 -> Industry | C72: =S6 -> 0.11 | D72: =T6 -> 0.11 | E72: =U6 -> 0.11 | F72: =V6 -> 0.11 | G72: =W6 -> 0.1045 | H72: =X6 -> 0.099 | ... M72: =AC6 -> 0.0825
A73: =Q7 -> CH | B73: =R7 -> Industry | C73: =S7 -> 0 | D73: =T7 -> 0 | E73: =U7 -> 0 | F73: =V7 -> 0 | G73: =W7 -> 0 | H73: =X7 -> 0 | ... M73: =AC7 -> 0
A74: =Q8 -> CZ | B74: =R8 -> Industry | C74: =S8 -> 0.34 | D74: =T8 -> 0.34 | E74: =U8 -> 0.34 | F74: =V8 -> 0.34 | G74: =W8 -> 0.323 | H74: =X8 -> 0.306 | ... M74: =AC8 -> 0.255
A75: =Q9 -> DE | B75: =R9 -> Industry | C75: =S9 -> 0.22 | D75: =T9 -> 0.22 | E75: =U9 -> 0.22 | F75: =V9 -> 0.22 | G75: =W9 -> 0.209 | H75: =X9 -> 0.198 | ... M75: =AC9 -> 0.165
A76: =Q10 -> DK | B76: =R10 -> Industry | C76: =S10 -> 0.05 | D76: =T10 -> 0.05 | E76: =U10 -> 0.05 | F76: =V10 -> 0.05 | G76: =W10 -> 0.0475 | H76: =X10 -> 0.045 | ... M76: =AC10 -> 0.0375
A77: =Q11 -> EE | B77: =R11 -> Industry | C77: =S11 -> 0.08 | D77: =T11 -> 0.08 | E77: =U11 -> 0.08 | F77: =V11 -> 0.08 | G77: =W11 -> 0.076 | H77: =X11 -> 0.072 | ... M77: =AC11 -> 0.06
A78: =Q12 -> ES | B78: =R12 -> Industry | C78: =S12 -> 0.22 | D78: =T12 -> 0.22 | E78: =U12 -> 0.22 | F78: =V12 -> 0.22 | G78: =W12 -> 0.209 | H78: =X12 -> 0.198 | ... M78: =AC12 -> 0.165
A79: =Q13 -> FI | B79: =R13 -> Industry | C79: =S13 -> 0.09 | D79: =T13 -> 0.09 | E79: =U13 -> 0.09 | F79: =V13 -> 0.09 | G79: =W13 -> 0.0855 | H79: =X13 -> 0.081 | ... M79: =AC13 -> 0.0675
A80: =Q14 -> FR | B80: =R14 -> Industry | C80: =S14 -> 0.13 | D80: =T14 -> 0.13 | E80: =U14 -> 0.13 | F80: =V14 -> 0.13 | G80: =W14 -> 0.1235 | H80: =X14 -> 0.117 | ... M80: =AC14 -> 0.0975
A81: =Q15 -> GR | B81: =R15 -> Industry | C81: =S15 -> 0 | D81: =T15 -> 0 | E81: =U15 -> 0 | F81: =V15 -> 0 | G81: =W15 -> 0 | H81: =X15 -> 0 | ... M81: =AC15 -> 0
...

Sheet Table2
A1: Region | B1: Fuel | C1: Year | D1: Value
A2: AT | B2: Heat_Buildings | C2: 2018 | D2: 0.84
A3: AT | B3: Heat_Buildings | C3: 2020 | D3: 0.84
A4: AT | B4: Heat_Buildings | C4: 2021 | D4: 0.84
A5: AT | B5: Heat_Buildings | C5: 2025 | D5: 0.84
A6: AT | B6: Heat_Buildings | C6: 2030 | D6: 0.8
A7: AT | B7: Heat_Buildings | C7: 2035 | D7: 0.76
A8: AT | B8: Heat_Buildings | C8: 2040 | D8: 0.71
A9: AT | B9: Heat_Buildings | C9: 2045 | D9: 0.67
A10: AT | B10: Heat_Buildings | C10: 2050 | D10: 0.63
A11: AT | B11: Heat_Buildings | C11: 2055 | D11: 0.63
A12: AT | B12: Heat_Buildings | C12: 2060 | D12: 0.63
A13: BE | B13: Heat_Buildings | C13: 2018 | D13: 0.73
... A661: UK | B661: Heat_Low_Industrial | C661: 2060 | D661: 0
